<lambdifygenerated-1>:3: RuntimeWarning: invalid value encountered in scalar subtract
  return [-18.4549964564139*b_0 - 0.0235890932149652*b_10 - 0.0289779808890736*b_11 - 112.048192771084*b_2 - 107.566265060241*b_3 + 27.9, 586.17313043898*b_1 - 2344.69252175592*b_2, -0.0646510714349216*b_10 + 2211.0666430743*b_2 - 98.2696285810805*b_3, -0.0143543452144606*b_10 - 0.00940457100257762*b_11 + 102.91794682066*b_3 - 972.002831084017*b_4 - 8.24977192768791*b_5 - 3.7736580500909*b_7, -0.00234725141871683*b_10 + 371.648141296827*b_4 - 3.10387458665486*b_5 - 0.343059822735536*b_7, -0.00333131508513074*b_11 + 4.60038749851387*b_5, -0.00789473684210532*b_10 - 0.00517241379310348*b_11 - 90.0000000000004*b_6 + 3.9, -0.000787147623988755*b_11 - 0.362337795169427*b_5 + 6.08727495884626*b_7, -0.0250952759361331*b_11 - 4.69903471927593*b_5 - 11.1014695242894*b_7 + 80.1772798976456*b_8, -0.0265839787459038*b_11 - 44.2937420413567*b_8 + 74.0097968285953*b_9, -937.877008702367*b_1 + 0.112836498125169*b_10 - 0.0169788079161635*b_11 + 21, 0.116331490992075*b_11 - 66.7209532015372*b_8 - 155.275456091368*b_9]
Traceback (most recent call last):
  File "C:\Users\Pablo\.texttest\tmp\foodweb.1_from_05Mär114835.6356\foodweb\ecosystems\controlSpaces\biomassDynamic\full_recipient\bothnian_Bay_Sandberg_2000\test.py", line 20, in <module>
    testData = Ecosystem(inputParameters, printer, "foodWebData.m", False)
               ^^^^^^^^^^^^^^^^^^^^^^^^^^^^^^^^^^^^^^^^^^^^^^^^^^^^^^^^^^^
  File "C:\Repositories\foodweb-dynamics-python\python\src\ecosystem\ecosystem.py", line 33, in __init__
    self.odeSolver = ODESolver(inputParameters, printer, self.generalModel, self.symbolicData, self.foodWebData, self.proportions)
                     ^^^^^^^^^^^^^^^^^^^^^^^^^^^^^^^^^^^^^^^^^^^^^^^^^^^^^^^^^^^^^^^^^^^^^^^^^^^^^^^^^^^^^^^^^^^^^^^^^^^^^^^^^^^^^
  File "C:\Repositories\foodweb-dynamics-python\python\src\ecosystem\ode\odeSolver.py", line 33, in __init__
    self.biomassFinal[i,0] = self.odeResult.y[i][1]
                             ~~~~~~~~~~~~~~~~~~~^^^
IndexError: index 1 is out of bounds for axis 0 with size 1
